I'm sorry, but an uncaught exception occurred.

While running game code:
  File "game/ch5.rpy", line 30, in script
    "離開[草原]，我開始朝著山坡前進。"
KeyError: u'\u8349\u539f'

-- Full Traceback ------------------------------------------------------------

Full traceback:
  File "game/ch5.rpy", line 30, in script
    "離開[草原]，我開始朝著山坡前進。"
  File "renpy/ast.py", line 721, in execute
    renpy.exports.say(who, what, *args, **kwargs)
  File "renpy/exports.py", line 1419, in say
    who(what, *args, **kwargs)
  File "renpy/character.py", line 1236, in __call__
    what = self.prefix_suffix("what", self.what_prefix, what, self.what_suffix)
  File "renpy/character.py", line 1155, in prefix_suffix
    return (sub(prefix) + sub(body) + sub(suffix))
  File "renpy/character.py", line 1135, in sub
    return renpy.substitutions.substitute(s, scope=scope, force=force, translate=translate)[0]
  File "renpy/substitutions.py", line 270, in substitute
    s = formatter.vformat(s, (), kwargs)
  File "/home/tom/ab/renpy-build/tmp/install.linux-x86_64/lib/python2.7/string.py", line 563, in vformat
  File "/home/tom/ab/renpy-build/tmp/install.linux-x86_64/lib/python2.7/string.py", line 585, in _vformat
  File "/home/tom/ab/renpy-build/tmp/install.linux-x86_64/lib/python2.7/string.py", line 646, in get_field
  File "/home/tom/ab/renpy-build/tmp/install.linux-x86_64/lib/python2.7/string.py", line 605, in get_value
KeyError: u'\u8349\u539f'

Windows-10-10.0.19041
Ren'Py 7.4.11.2266
Da Capo 1.0
Fri Jan  7 22:25:18 2022
